Workbook

Sheet Individuals
A1: Person ID | B1: Full Name | C1: Sex | D1: Birth Date | E1: Birth Place | F1: Death Date | G1: Death Place
A2: 1 | B2: Somasuntharam | C2: M
A3: 2 | B3: Arunasalam | C3: M
A4: 3 | B4: Bavani | C4: F
A5: 4 | B5: Somasundarampillai | C5: M
A6: 5 | B6: Leelavathi | C6: F
A7: 6 | B7: Viknarasah | C7: M
A8: 7 | B8: Raja Rajeswari | C8: F
A9: 8 | B9: Kulaveerasingham | C9: M
A10: 9 | B10: Bhuvaneswari | C10: F
A11: 10 | B11: Arunachalam | C11: M
A12: 11 | B12: Valliammai | C12: F
A13: 12 | B13: Chelliah | C13: M
A14: 13 | B14: Thangamuthu | C14: F
A15: 14 | B15: Arumugam | C15: M
A16: 15 | B16: Rasarathinam | C16: F
A17: 16 | B17: Somasundaram | C17: M
A18: 17 | B18: Rajeswary | C18: F
A19: 18 | B19: Murugesar | C19: M
A20: 19 | B20: Paruvathipillai | C20: F
A21: 20 | B21: Narayana sasthiriyar | C21: M
A22: 21 | B22: Theivanapillai | C22: F
A23: 22 | B23: Sasthiriyar | C23: M
A24: 23 | B24: unknown | C24: F
... A32: 31 | B32: unknown | C32: F
A33: 32 | B33: Mappanar | C33: M | D33: 1820 | E33: Puloly north | F33: 1885 | G33: Puloly north
A34: 33 | B34: Parvathipillai | C34: F
A35: 34 | B35: Somasundaram | C35: M
A36: 35 | B36: unknown | C36: F
A37: 36 | B37: Vallipuranathar | C37: M
A38: 37 | B38: Chinnachipillai | C38: F
A39: 38 | B39: Vaalar | C39: M
A40: 39 | B40: Chinnapillai | C40: F
A41: 40 | B41: Kanthar | C41: M
A42: 41 | B42: Chokkathai | C42: F
A43: 42 | B43: Maniyagar Chattambi Alvainar | C43: M
A44: 43 | B44: Nasakapillai | C44: F
A45: 44 | B45: Ananthar (Rajasurya Maapana Mudaliyar) | C45: M
... A100: 99 | B100: unknown | C100: F

Sheet Families
A1: Family ID | B1: Husband ID | C1: Husband Name | D1: Wife ID | E1: Wife Name | F1: Marriage Date | G1: Marriage Place | H1: Children IDs (comma-separated)
A2: F1 | B2: 2 | C2: {=XLOOKUP(B2,Individuals!A:A,Individuals!B:B)} -> Arunasalam | D2: 3 | E2: {=XLOOKUP(D2,Individuals!A:A,Individuals!B:B)} -> Bavani | H2: 1
A3: F2 | B3: 4 | C3: {=XLOOKUP(B3,Individuals!A:A,Individuals!B:B)} -> Somasundarampillai | D3: 5 | E3: {=XLOOKUP(D3,Individuals!A:A,Individuals!B:B)} -> Leelavathi | H3: 2
A4: F3 | B4: 6 | C4: {=XLOOKUP(B4,Individuals!A:A,Individuals!B:B)} -> Viknarasah | D4: 7 | E4: {=XLOOKUP(D4,Individuals!A:A,Individuals!B:B)} -> Raja Rajeswari | H4: 3
A5: F4 | B5: 8 | C5: {=XLOOKUP(B5,Individuals!A:A,Individuals!B:B)} -> Kulaveerasingham | D5: 9 | E5: {=XLOOKUP(D5,Individuals!A:A,Individuals!B:B)} -> Bhuvaneswari | H5: 5,6
A6: F5 | B6: 10 | C6: {=XLOOKUP(B6,Individuals!A:A,Individuals!B:B)} -> Arunachalam | D6: 11 | E6: {=XLOOKUP(D6,Individuals!A:A,Individuals!B:B)} -> Valliammai | H6: 4,7
A7: F6 | B7: 12 | C7: {=XLOOKUP(B7,Individuals!A:A,Individuals!B:B)} -> Chelliah | D7: 13 | E7: {=XLOOKUP(D7,Individuals!A:A,Individuals!B:B)} -> Thangamuthu | H7: 8
A8: F7 | B8: 14 | C8: {=XLOOKUP(B8,Individuals!A:A,Individuals!B:B)} -> Arumugam | D8: 15 | E8: {=XLOOKUP(D8,Individuals!A:A,Individuals!B:B)} -> Rasarathinam | H8: 9
A9: F8 | B9: 16 | C9: {=XLOOKUP(B9,Individuals!A:A,Individuals!B:B)} -> Somasundaram | D9: 17 | E9: {=XLOOKUP(D9,Individuals!A:A,Individuals!B:B)} -> Rajeswary | H9: 10
A10: F9 | B10: 18 | C10: {=XLOOKUP(B10,Individuals!A:A,Individuals!B:B)} -> Murugesar | D10: 19 | E10: {=XLOOKUP(D10,Individuals!A:A,Individuals!B:B)} -> Paruvathipillai | H10: 12
A11: F10 | B11: 20 | C11: {=XLOOKUP(B11,Individuals!A:A,Individuals!B:B)} -> Narayana sasthiriyar | D11: 21 | E11: {=XLOOKUP(D11,Individuals!A:A,Individuals!B:B)} -> Theivanapillai | H11: 13
A12: F11 | B12: 22 | C12: {=XLOOKUP(B12,Individuals!A:A,Individuals!B:B)} -> Sasthiriyar | D12: 23 | E12: {=XLOOKUP(D12,Individuals!A:A,Individuals!B:B)} -> unknown | H12: 14
A13: F12 | B13: 24 | C13: {=XLOOKUP(B13,Individuals!A:A,Individuals!B:B)} -> Velupillai | D13: 25 | E13: {=XLOOKUP(D13,Individuals!A:A,Individuals!B:B)} -> Sinnathangam | H13: 15
A14: F13 | B14: 26 | C14: {=XLOOKUP(B14,Individuals!A:A,Individuals!B:B)} -> Arunasalam | D14: 27 | E14: {=XLOOKUP(D14,Individuals!A:A,Individuals!B:B)} -> unknown | H14: 16
A15: F14 | B15: 28 | C15: {=XLOOKUP(B15,Individuals!A:A,Individuals!B:B)} -> Subramaniapillai | D15: 29 | E15: {=XLOOKUP(D15,Individuals!A:A,Individuals!B:B)} -> Valliammai | H15: 17
A16: F15 | B16: 30 | C16: {=XLOOKUP(B16,Individuals!A:A,Individuals!B:B)} -> Sinnavar | D16: 31 | E16: {=XLOOKUP(D16,Individuals!A:A,Individuals!B:B)} -> unknown | H16: 18,24
A17: F16 | B17: 32 | C17: {=XLOOKUP(B17,Individuals!A:A,Individuals!B:B)} -> Mappanar | D17: 33 | E17: {=XLOOKUP(D17,Individuals!A:A,Individuals!B:B)} -> Parvathipillai | H17: 21,25
A18: F17 | B18: 34 | C18: {=XLOOKUP(B18,Individuals!A:A,Individuals!B:B)} -> Somasundaram | D18: 35 | E18: {=XLOOKUP(D18,Individuals!A:A,Individuals!B:B)} -> unknown | H18: 26
A19: F18 | B19: 36 | C19: {=XLOOKUP(B19,Individuals!A:A,Individuals!B:B)} -> Vallipuranathar | D19: 37 | E19: {=XLOOKUP(D19,Individuals!A:A,Individuals!B:B)} -> Chinnachipillai | H19: 28
A20: F19 | B20: 38 | C20: {=XLOOKUP(B20,Individuals!A:A,Individuals!B:B)} -> Vaalar | D20: 39 | E20: {=XLOOKUP(D20,Individuals!A:A,Individuals!B:B)} -> Chinnapillai | H20: 30
A21: F20 | B21: 40 | C21: {=XLOOKUP(B21,Individuals!A:A,Individuals!B:B)} -> Kanthar | D21: 41 | E21: {=XLOOKUP(D21,Individuals!A:A,Individuals!B:B)} -> Chokkathai | H21: 32
A22: F21 | B22: 42 | C22: {=XLOOKUP(B22,Individuals!A:A,Individuals!B:B)} -> Maniyagar Chattambi Alvainar | D22: 43 | E22: {=XLOOKUP(D22,Individuals!A:A,Individuals!B:B)} -> Nasakapillai | H22: 33
A23: F22 | B23: 44 | C23: {=XLOOKUP(B23,Individuals!A:A,Individuals!B:B)} -> Ananthar (Rajasurya Maapana Mudaliyar) | D23: 45 | E23: {=XLOOKUP(D23,Individuals!A:A,Individuals!B:B)} -> Nasakapillai | H23: 38
A24: F23 | B24: 46 | C24: {=XLOOKUP(B24,Individuals!A:A,Individuals!B:B)} -> Kathiravelu udayar | D24: 47 | E24: {=XLOOKUP(D24,Individuals!A:A,Individuals!B:B)} -> Nachchan | H24: 39
A25: F24 | B25: 48 | C25: {=XLOOKUP(B25,Individuals!A:A,Individuals!B:B)} -> Mappanar | D25: 49 | E25: {=XLOOKUP(D25,Individuals!A:A,Individuals!B:B)} -> Sembi | H25: 40
A26: F25 | B26: 50 | C26: {=XLOOKUP(B26,Individuals!A:A,Individuals!B:B)} -> Kathiran | D26: 51 | E26: {=XLOOKUP(D26,Individuals!A:A,Individuals!B:B)} -> Chinnathai | H26: 41
A27: F26 | B27: 52 | C27: {=XLOOKUP(B27,Individuals!A:A,Individuals!B:B)} -> Velayuthar | D27: 53 | E27: {=XLOOKUP(D27,Individuals!A:A,Individuals!B:B)} -> unknown | H27: 42
A28: F27 | B28: 54 | C28: {=XLOOKUP(B28,Individuals!A:A,Individuals!B:B)} -> Ananthavalliar | D28: 55 | E28: {=XLOOKUP(D28,Individuals!A:A,Individuals!B:B)} -> unknown | H28: 44
A29: F28 | B29: 56 | C29: {=XLOOKUP(B29,Individuals!A:A,Individuals!B:B)} -> Nagamaniyar | D29: 57 | E29: {=XLOOKUP(D29,Individuals!A:A,Individuals!B:B)} -> unknown | H29: 45,46
A30: F29 | B30: 58 | C30: {=XLOOKUP(B30,Individuals!A:A,Individuals!B:B)} -> Veerasundara Mudali (Thunnalai chief) | D30: 59 | E30: {=XLOOKUP(D30,Individuals!A:A,Individuals!B:B)} -> unknown | H30: 47
A31: F30 | B31: 60 | C31: {=XLOOKUP(B31,Individuals!A:A,Individuals!B:B)} -> Kandappar Mappana Mudaliyar (Malavaraya Mudali) | D31: 61 | E31: {=XLOOKUP(D31,Individuals!A:A,Individuals!B:B)} -> unknown | H31: 48
A32: F31 | B32: 62 | C32: {=XLOOKUP(B32,Individuals!A:A,Individuals!B:B)} -> Velan | D32: 63 | E32: {=XLOOKUP(D32,Individuals!A:A,Individuals!B:B)} -> Chokkathai | H32: 49,50
A33: F32 | B33: 64 | C33: {=XLOOKUP(B33,Individuals!A:A,Individuals!B:B)} -> Vaariyar | D33: 65 | E33: {=XLOOKUP(D33,Individuals!A:A,Individuals!B:B)} -> Paramathai | H33: 51
A34: F33 | B34: 66 | C34: {=XLOOKUP(B34,Individuals!A:A,Individuals!B:B)} -> Singabahudeva Mudali | D34: 67 | E34: {=XLOOKUP(D34,Individuals!A:A,Individuals!B:B)} -> unknown | H34: 52
A35: F34 | B35: 68 | C35: {=XLOOKUP(B35,Individuals!A:A,Individuals!B:B)} -> Alvainar | D35: 69 | E35: {=XLOOKUP(D35,Individuals!A:A,Individuals!B:B)} -> unknown | H35: 54
A36: F35 | B36: 70 | C36: {=XLOOKUP(B36,Individuals!A:A,Individuals!B:B)} -> Velayuthar | D36: 71 | E36: {=XLOOKUP(D36,Individuals!A:A,Individuals!B:B)} -> unknown | H36: 56
A37: F36 | B37: 72 | C37: {=XLOOKUP(B37,Individuals!A:A,Individuals!B:B)} -> Santhayinar Mappana Mudaliyar | D37: 73 | E37: {=XLOOKUP(D37,Individuals!A:A,Individuals!B:B)} -> unknown | H37: 60
A38: F37 | B38: 74 | C38: {=XLOOKUP(B38,Individuals!A:A,Individuals!B:B)} -> Sanmar | D38: 75 | E38: {=XLOOKUP(D38,Individuals!A:A,Individuals!B:B)} -> Santhirari | H38: 62,65
A39: F38 | B39: 76 | C39: {=XLOOKUP(B39,Individuals!A:A,Individuals!B:B)} -> Kanthar | D39: 77 | E39: {=XLOOKUP(D39,Individuals!A:A,Individuals!B:B)} -> Sembi | H39: 63,64
A40: F39 | B40: 78 | C40: {=XLOOKUP(B40,Individuals!A:A,Individuals!B:B)} -> Pararasasekaran | D40: 79 | E40: {=XLOOKUP(D40,Individuals!A:A,Individuals!B:B)} -> unknown | H40: 66
...
